Workbook
Name Slicer_Category: #N/A
Name Slicer_Income_Source: #N/A
Name Slicer_Month: #N/A
Name Slicer_Payment_Method: #N/A
Name Slicer_Payment_Method1: #N/A

Sheet Welcome Page
A1: PERSONAL FINANCE & BUDGET PLANNER
A3: PRESENTED BY
A4: Aakash Nath & Abhijit Roy
B6: 📄 RAW DATA | J6: 📈 PIVOT TABLES
B7: View original financial records | J7: Category-wise expense monitoring and comparison
B9: 🧹 CLEANING TASKS | J9: 💰 INCOME ANALYSIS
B10: Steps performed for data cleaning and preprocessing | J10: Monthly income tracking and trend analysis
B12: ✅ CLEANED DATA | J12: 💸 EXPENSE ANALYSIS
B13: Processed and structured financial dataset | J13: Category-wise expense monitoring and comparison
B15: 📊 FINAL DASHBOARD | J15: 🏦 BUDGET ANALYSIS
B16: Interactive charts, KPIs and insights | J16: Budget planning versus actual spending

Sheet Raw Data
A1: RAW DATA
A2: Id | B2: Date | C2: Month | D2: Person Name | E2: Age | F2: City | G2: Income Source | H2: Monthly Income | I2: ExpenseCategory | J2: Expense Amount | K2: Payment Method | L2: Savings | M2: Loan EMI | N2: Credit Score | O2: Financial Status
A3: TXN1001 | B3: 45659 | C3: January | D3: Rahul Sen | E3: 29 | F3: Kolkata | G3: Salary | H3: 65000 | I3: Rent | J3: 18000 | K3: UPI | L3: 12000 | M3: 5000 | N3: 742 | O3: Stable
A4: TXN1002 | B4: 45660 | C4: February | D4: Priya Das | E4: 34 | F4: Mumbai | G4: Freelancing | H4: 72000 | I4: Groceries | J4: 6500 | K4: Card | L4: 15000 | N4: 788 | O4: Good
A5: TXN1003 | B5: 45661 | C5: March | D5: Ankit Roy | E5: 26 | G5: Salary | H5: 54000 | J5: 3200 | K5: Cash | L5: 8000 | M5: 2500 | N5: 689 | O5: Average
A6: TXN1004 | B6: 45662 | C6: April | D6: Sneha Paul | E6: 31 | F6: Bangalore | G6: Business | H6: 98000 | I6: Utilities | J6: 5400 | K6: NetBanking | L6: 25000 | M6: 8000 | N6: 801 | O6: Excellent
A7: TXN1005 | B7: 45663 | C7: May | D7: Rohan Mitra | E7: 38 | F7: Hyderabad | G7: Salary | H7: 85000 | I7: Entertainment | J7: 7600 | K7: Card | L7: 10000 | M7: 12000 | N7: 655 | O7: Risky
A8: TXN1006 | B8: 45664 | C8: June | D8: Aditi Sharma | E8: 27 | F8: Pune | H8: 61000 | I8: Healthcare | J8: 2400 | K8: UPI | L8: 17000 | N8: 771 | O8: Good
A9: TXN1007 | B9: 45665 | C9: July | D9: Karan Singh | E9: 42 | F9: Chennai | G9: Business | H9: 120000 | I9: Rent | J9: 25000 | K9: Cheque | L9: 35000 | M9: 18000 | N9: 720 | O9: Stable
A10: TXN1008 | B10: 45666 | C10: August | D10: Megha Dutta | E10: 24 | F10: Kolkata | G10: Internship | H10: 28000 | I10: Education | J10: 4500 | K10: UPI | L10: 5000 | N10: 690 | O10: Average
A11: TXN1009 | B11: 45667 | C11: September | D11: Arjun Nair | E11: 36 | F11: Kochi | G11: Salary | H11: 76000 | J11: 8200 | K11: Card | L11: 14000 | M11: 7000 | N11: 745 | O11: Stable
A12: TXN1010 | B12: 45668 | C12: October | D12: Neha Kapoor | E12: 30 | F12: Jaipur | G12: Freelancing | H12: 68000 | I12: Shopping | J12: 9200 | K12: UPI | L12: 11000 | M12: 3000 | N12: 732 | O12: Good
A13: TXN1011 | B13: 45669 | C13: November | D13: Vikram Bose | E13: 45 | F13: Kolkata | G13: Business | H13: 150000 | I13: Investment | J13: 35000 | K13: NetBanking | L13: 40000 | M13: 20000 | N13: 810 | O13: Excellent
A14: TXN1012 | B14: 45670 | C14: December | D14: Isha Jain | E14: 28 | F14: Delhi | H14: 59000 | I14: Food | J14: 5800 | L14: 9000 | M14: 2500 | N14: 704 | O14: Stable
A15: TXN1013 | B15: 45671 | C15: January | D15: Sourav Ghosh | E15: 33 | G15: Salary | H15: 71000 | I15: Rent | J15: 21000 | K15: UPI | L15: 13000 | M15: 6000 | N15: 740 | O15: Good
A16: TXN1014 | B16: 45672 | C16: February | D16: Ritika Sen | E16: 25 | F16: Pune | G16: Freelancing | H16: 47000 | I16: Entertainment | J16: 4200 | K16: Card | L16: 7000 | N16: 681 | O16: Average
A17: TXN1015 | B17: 45673 | C17: March | D17: Abhishek Das | E17: 39 | F17: Bangalore | G17: Business | H17: 132000 | I17: Healthcare | J17: 6800 | K17: NetBanking | L17: 30000 | M17: 15000 | N17: 790 | O17: Excellent
A18: TXN1016 | B18: 45674 | C18: April | D18: Nikita Roy | E18: 29 | F18: Delhi | G18: Salary | H18: 62000 | I18: Groceries | J18: 5900 | K18: UPI | L18: 12000 | M18: 3000 | N18: 725 | O18: Good
A19: TXN1017 | B19: 45675 | C19: May | D19: Manish Yadav | E19: 35 | F19: Mumbai | G19: Salary | H19: 81000 | I19: Transport | J19: 4100 | K19: Cash | L19: 16000 | M19: 9000 | N19: 710 | O19: Stable
A20: TXN1018 | B20: 45676 | C20: June | D20: Simran Kaur | E20: 27 | F20: Chandigarh | G20: Freelancing | H20: 56000 | J20: 9700 | K20: Card | L20: 8500 | N20: 699 | O20: Average
A21: TXN1019 | B21: 45677 | C21: July | D21: Raj Malhotra | E21: 41 | F21: Delhi | G21: Business | H21: 145000 | I21: Utilities | J21: 7800 | K21: Cheque | L21: 42000 | M21: 25000 | N21: 805 | O21: Excellent
A22: TXN1020 | B22: 45678 | C22: August | D22: Pooja Mehta | E22: 32 | F22: Ahmedabad | G22: Salary | H22: 69000 | I22: Food | J22: 6300 | K22: UPI | L22: 10000 | M22: 4500 | N22: 730 | O22: Good
A23: TXN1021 | B23: 45679 | C23: September | D23: Deepak Kumar | E23: 37 | F23: Patna | G23: Salary | H23: 57000 | I23: Rent | J23: 16000 | K23: Cash | L23: 6000 | M23: 5500 | N23: 670 | O23: Risky
A24: TXN1022 | B24: 45680 | C24: October | D24: Tanvi Shah | E24: 26 | F24: Surat | G24: Freelancing | H24: 52000 | I24: Shopping | J24: 7600 | K24: Card | L24: 9000 | N24: 715 | O24: Stable
A25: TXN1023 | B25: 45681 | C25: November | D25: Ritesh Verma | E25: 40 | H25: 125000 | I25: Investment | J25: 28000 | K25: NetBanking | L25: 37000 | M25: 12000 | N25: 798 | O25: Excellent
A26: TXN1024 | B26: 45682 | C26: December | D26: Ananya Ghosh | E26: 31 | F26: Kolkata | G26: Salary | H26: 74000 | I26: Education | J26: 5300 | K26: UPI | L26: 15000 | M26: 5000 | N26: 750 | O26: Good
A27: TXN1025 | B27: 45683 | C27: January | D27: Kunal Sharma | E27: 28 | F27: Delhi | G27: Salary | H27: 63000 | J27: 8600 | K27: Card | L27: 11000 | M27: 3500 | N27: 721 | O27: Stable
A28: TXN1075 | B28: 45733 | C28: February | D28: Amit Bose | E28: 36 | F28: Kolkata | G28: Salary | H28: 81000 | I28: Travel | J28: 9400 | K28: UPI | L28: 17000 | M28: 8500 | N28: 743 | O28: Good
A29: TXN1076 | B29: 45734 | C29: March | D29: Sonia Jain | E29: 27 | F29: Pune | G29: Freelancing | H29: 55000 | I29: Food | J29: 5200 | K29: Card | L29: 8000 | N29: 701 | O29: Stable
A30: TXN1077 | B30: 45735 | C30: April | D30: Harsh Vardhan | E30: 43 | F30: Delhi | G30: Business | H30: 149000 | I30: Investment | J30: 41000 | K30: Cheque | L30: 50000 | M30: 23000 | N30: 815 | O30: Excellent
A31: TXN1078 | B31: 45736 | C31: May | D31: Ankita Sen | E31: 30 | F31: Kolkata | G31: Salary | H31: 72000 | I31: Utilities | J31: 6300 | K31: UPI | L31: 14500 | M31: 3500 | N31: 735 | O31: Good
A32: TXN1079 | B32: 45737 | C32: June | D32: Rohan Sharma | E32: 28 | F32: Delhi | G32: Salary | H32: 65000 | I32: Transport | J32: 4800 | K32: Cash | L32: 10000 | M32: 4000 | N32: 712 | O32: Stable
A33: TXN1080 | B33: 45738 | C33: July | D33: Priya Roy | E33: 25 | F33: Kolkata | G33: Freelancing | H33: 50000 | I33: Shopping | J33: 8100 | K33: Card | L33: 6000 | N33: 689 | O33: Average
A34: TXN1081 | B34: 45739 | C34: August | D34: Abhishek Jain | E34: 40 | F34: Mumbai | H34: 137000 | I34: Rent | J34: 33000 | L34: 41000 | M34: 17000 | N34: 799 | O34: Excellent
A35: TXN1082 | B35: 45740 | C35: September | D35: Tania Das | E35: 31 | F35: Kolkata | G35: Salary | H35: 70000 | I35: Healthcare | J35: 4600 | K35: UPI | L35: 13000 | M35: 3000 | N35: 732 | O35: Good
A36: TXN1083 | B36: 45741 | C36: October | D36: Manish Roy | E36: 35 | F36: Delhi | G36: Salary | H36: 83000 | I36: Travel | J36: 10200 | K36: Card | L36: 18000 | M36: 9500 | N36: 747 | O36: Good
A37: TXN1084 | B37: 45742 | C37: November | D37: Sweta Kapoor | E37: 26 | F37: Pune | G37: Freelancing | H37: 53000 | I37: Entertainment | J37: 4100 | K37: Cash | L37: 7000 | N37: 694 | O37: Average
A38: TXN1085 | B38: 45743 | C38: December | D38: Kunal Verma | E38: 42 | F38: Ahmedabad | G38: Business | H38: 144000 | I38: Investment | J38: 37000 | K38: Cheque | L38: 46000 | M38: 21000 | N38: 810 | O38: Excellent
A39: TXN1086 | B39: 45744 | C39: January | D39: Megha Roy | E39: 29 | F39: Kolkata | G39: Salary | H39: 69000 | I39: Groceries | J39: 6200 | K39: UPI | L39: 12500 | M39: 3000 | N39: 728 | O39: Good
A40: TXN1087 | B40: 45745 | C40: February | D40: Rajat Das | E40: 33 | G40: Salary | H40: 78000 | I40: Rent | J40: 22000 | K40: Card | L40: 15000 | M40: 7000 | N40: 739 | O40: Good
...

Sheet Cleaning Tasks
A1: DATA CLEANING PROCESS
A2: Id | B2: Date | C2: Month | D2: Person Name | E2: Age | F2: City | G2: Income Source | H2: Monthly Income | I2: Expense Category | J2: Expense Amount | K2: Payment Method | L2: Savings | M2: Loan EMI | N2: Credit Score | O2: Financial Status | P2: City2 | Q2: Income Source2 | R2: Expense Category2 | S2: Loan EMI2 | T2: Payment Method2
A3: TXN1001 | B3: 45659 | C3: January | D3: Rahul Sen | E3: 29 | F3: Kolkata | G3: Salary | H3: 65000 | I3: Rent | J3: 18000 | K3: UPI | L3: 12000 | M3: 5000 | N3: 742 | O3: Stable | P3: =IF(COUNTBLANK(#REF!)=0,#REF!,"Unknown") -> Kolkata | Q3: =IF(COUNTBLANK(#REF!)=0,#REF!,"Unknown") -> Salary | R3: =IF(COUNTBLANK(#REF!)=0,#REF!,"Unknown") -> Rent | S3: =IF(COUNTBLANK(#REF!)=0,#REF!,0) -> 5000 | T3: =IF(COUNTBLANK(K3)=0,K3,"Cash/UPI") -> UPI
A4: TXN1002 | B4: 45660 | C4: February | D4: Priya Das | E4: 34 | F4: Mumbai | G4: Freelancing | H4: 72000 | I4: Groceries | J4: 6500 | K4: Card | L4: 15000 | N4: 788 | O4: Good | P4: =IF(COUNTBLANK(#REF!)=0,#REF!,"Unknown") -> Mumbai | Q4: =IF(COUNTBLANK(#REF!)=0,#REF!,"Unknown") -> Freelancing | R4: =IF(COUNTBLANK(#REF!)=0,#REF!,"Unknown") -> Groceries | S4: =IF(COUNTBLANK(#REF!)=0,#REF!,0) -> 0 | T4: =IF(COUNTBLANK(K4)=0,K4,"Cash/UPI") -> Card
A5: TXN1003 | B5: 45661 | C5: March | D5: Ankit Roy | E5: 26 | G5: Salary | H5: 54000 | J5: 3200 | K5: Cash | L5: 8000 | M5: 2500 | N5: 689 | O5: Average | P5: =IF(COUNTBLANK(#REF!)=0,#REF!,"Unknown") -> Unknown | Q5: =IF(COUNTBLANK(#REF!)=0,#REF!,"Unknown") -> Salary | R5: =IF(COUNTBLANK(#REF!)=0,#REF!,"Unknown") -> Unknown | S5: =IF(COUNTBLANK(#REF!)=0,#REF!,0) -> 2500 | T5: =IF(COUNTBLANK(K5)=0,K5,"Cash/UPI") -> Cash
A6: TXN1004 | B6: 45662 | C6: April | D6: Sneha Paul | E6: 31 | F6: Bangalore | G6: Business | H6: 98000 | I6: Utilities | J6: 5400 | K6: NetBanking | L6: 25000 | M6: 8000 | N6: 801 | O6: Excellent | P6: =IF(COUNTBLANK(#REF!)=0,#REF!,"Unknown") -> Bangalore | Q6: =IF(COUNTBLANK(#REF!)=0,#REF!,"Unknown") -> Business | R6: =IF(COUNTBLANK(#REF!)=0,#REF!,"Unknown") -> Utilities | S6: =IF(COUNTBLANK(#REF!)=0,#REF!,0) -> 8000 | T6: =IF(COUNTBLANK(K6)=0,K6,"Cash/UPI") -> NetBanking
A7: TXN1005 | B7: 45663 | C7: May | D7: Rohan Mitra | E7: 38 | F7: Hyderabad | G7: Salary | H7: 85000 | I7: Entertainment | J7: 7600 | K7: Card | L7: 10000 | M7: 12000 | N7: 655 | O7: Risky | P7: =IF(COUNTBLANK(#REF!)=0,#REF!,"Unknown") -> Hyderabad | Q7: =IF(COUNTBLANK(#REF!)=0,#REF!,"Unknown") -> Salary | R7: =IF(COUNTBLANK(#REF!)=0,#REF!,"Unknown") -> Entertainment | S7: =IF(COUNTBLANK(#REF!)=0,#REF!,0) -> 12000 | T7: =IF(COUNTBLANK(K7)=0,K7,"Cash/UPI") -> Card
A8: TXN1006 | B8: 45664 | C8: June | D8: Aditi Sharma | E8: 27 | F8: Pune | G8: =IF(COUNTBLANK(G3)=0,G3,"UKNOWN") -> Salary | H8: 61000 | I8: Healthcare | J8: 2400 | K8: UPI | L8: 17000 | N8: 771 | O8: Good | P8: =IF(COUNTBLANK(#REF!)=0,#REF!,"Unknown") -> Pune | Q8: =IF(COUNTBLANK(#REF!)=0,#REF!,"Unknown") -> Salary | R8: =IF(COUNTBLANK(#REF!)=0,#REF!,"Unknown") -> Healthcare | S8: =IF(COUNTBLANK(#REF!)=0,#REF!,0) -> 0 | T8: =IF(COUNTBLANK(K8)=0,K8,"Cash/UPI") -> UPI
A9: TXN1007 | B9: 45665 | C9: July | D9: Karan Singh | E9: 42 | F9: Chennai | G9: Business | H9: 120000 | I9: Rent | J9: 25000 | K9: Cheque | L9: 35000 | M9: 18000 | N9: 720 | O9: Stable | P9: =IF(COUNTBLANK(#REF!)=0,#REF!,"Unknown") -> Chennai | Q9: =IF(COUNTBLANK(#REF!)=0,#REF!,"Unknown") -> Business | R9: =IF(COUNTBLANK(#REF!)=0,#REF!,"Unknown") -> Rent | S9: =IF(COUNTBLANK(#REF!)=0,#REF!,0) -> 18000 | T9: =IF(COUNTBLANK(K9)=0,K9,"Cash/UPI") -> Cheque
A10: TXN1008 | B10: 45666 | C10: August | D10: Megha Dutta | E10: 24 | F10: Kolkata | G10: Internship | H10: 28000 | I10: Education | J10: 4500 | K10: UPI | L10: 5000 | N10: 690 | O10: Average | P10: =IF(COUNTBLANK(#REF!)=0,#REF!,"Unknown") -> Kolkata | Q10: =IF(COUNTBLANK(#REF!)=0,#REF!,"Unknown") -> Internship | R10: =IF(COUNTBLANK(#REF!)=0,#REF!,"Unknown") -> Education | S10: =IF(COUNTBLANK(#REF!)=0,#REF!,0) -> 0 | T10: =IF(COUNTBLANK(K10)=0,K10,"Cash/UPI") -> UPI
A11: TXN1009 | B11: 45667 | C11: September | D11: Arjun Nair | E11: 36 | F11: Kochi | G11: Salary | H11: 76000 | J11: 8200 | K11: Card | L11: 14000 | M11: 7000 | N11: 745 | O11: Stable | P11: =IF(COUNTBLANK(#REF!)=0,#REF!,"Unknown") -> Kochi | Q11: =IF(COUNTBLANK(#REF!)=0,#REF!,"Unknown") -> Salary | R11: =IF(COUNTBLANK(#REF!)=0,#REF!,"Unknown") -> Unknown | S11: =IF(COUNTBLANK(#REF!)=0,#REF!,0) -> 7000 | T11: =IF(COUNTBLANK(K11)=0,K11,"Cash/UPI") -> Card
A12: TXN1010 | B12: 45668 | C12: October | D12: Neha Kapoor | E12: 30 | F12: Jaipur | G12: Freelancing | H12: 68000 | I12: Shopping | J12: 9200 | K12: UPI | L12: 11000 | M12: 3000 | N12: 732 | O12: Good | P12: =IF(COUNTBLANK(#REF!)=0,#REF!,"Unknown") -> Jaipur | Q12: =IF(COUNTBLANK(#REF!)=0,#REF!,"Unknown") -> Freelancing | R12: =IF(COUNTBLANK(#REF!)=0,#REF!,"Unknown") -> Shopping | S12: =IF(COUNTBLANK(#REF!)=0,#REF!,0) -> 3000 | T12: =IF(COUNTBLANK(K12)=0,K12,"Cash/UPI") -> UPI
A13: TXN1011 | B13: 45669 | C13: November | D13: Vikram Bose | E13: 45 | F13: Kolkata | G13: Business | H13: 150000 | I13: Investment | J13: 35000 | K13: NetBanking | L13: 40000 | M13: 20000 | N13: 810 | O13: Excellent | P13: =IF(COUNTBLANK(#REF!)=0,#REF!,"Unknown") -> Kolkata | Q13: =IF(COUNTBLANK(#REF!)=0,#REF!,"Unknown") -> Business | R13: =IF(COUNTBLANK(#REF!)=0,#REF!,"Unknown") -> Investment | S13: =IF(COUNTBLANK(#REF!)=0,#REF!,0) -> 20000 | T13: =IF(COUNTBLANK(K13)=0,K13,"Cash/UPI") -> NetBanking
A14: TXN1012 | B14: 45670 | C14: December | D14: Isha Jain | E14: 28 | F14: Delhi | H14: 59000 | I14: Food | J14: 5800 | L14: 9000 | M14: 2500 | N14: 704 | O14: Stable | P14: =IF(COUNTBLANK(#REF!)=0,#REF!,"Unknown") -> Delhi | Q14: =IF(COUNTBLANK(#REF!)=0,#REF!,"Unknown") -> Unknown | R14: =IF(COUNTBLANK(#REF!)=0,#REF!,"Unknown") -> Food | S14: =IF(COUNTBLANK(#REF!)=0,#REF!,0) -> 2500 | T14: =IF(COUNTBLANK(K14)=0,K14,"Cash/UPI") -> Cash/UPI
A15: TXN1013 | B15: 45671 | C15: January | D15: Sourav Ghosh | E15: 33 | G15: Salary | H15: 71000 | I15: Rent | J15: 21000 | K15: UPI | L15: 13000 | M15: 6000 | N15: 740 | O15: Good | P15: =IF(COUNTBLANK(#REF!)=0,#REF!,"Unknown") -> Unknown | Q15: =IF(COUNTBLANK(#REF!)=0,#REF!,"Unknown") -> Salary | R15: =IF(COUNTBLANK(#REF!)=0,#REF!,"Unknown") -> Rent | S15: =IF(COUNTBLANK(#REF!)=0,#REF!,0) -> 6000 | T15: =IF(COUNTBLANK(K15)=0,K15,"Cash/UPI") -> UPI
A16: TXN1014 | B16: 45672 | C16: February | D16: Ritika Sen | E16: 25 | F16: Pune | G16: Freelancing | H16: 47000 | I16: Entertainment | J16: 4200 | K16: Card | L16: 7000 | N16: 681 | O16: Average | P16: =IF(COUNTBLANK(#REF!)=0,#REF!,"Unknown") -> Pune | Q16: =IF(COUNTBLANK(#REF!)=0,#REF!,"Unknown") -> Freelancing | R16: =IF(COUNTBLANK(#REF!)=0,#REF!,"Unknown") -> Entertainment | S16: =IF(COUNTBLANK(#REF!)=0,#REF!,0) -> 0 | T16: =IF(COUNTBLANK(K16)=0,K16,"Cash/UPI") -> Card
A17: TXN1015 | B17: 45673 | C17: March | D17: Abhishek Das | E17: 39 | F17: Bangalore | G17: Business | H17: 132000 | I17: Healthcare | J17: 6800 | K17: NetBanking | L17: 30000 | M17: 15000 | N17: 790 | O17: Excellent | P17: =IF(COUNTBLANK(#REF!)=0,#REF!,"Unknown") -> Bangalore | Q17: =IF(COUNTBLANK(#REF!)=0,#REF!,"Unknown") -> Business | R17: =IF(COUNTBLANK(#REF!)=0,#REF!,"Unknown") -> Healthcare | S17: =IF(COUNTBLANK(#REF!)=0,#REF!,0) -> 15000 | T17: =IF(COUNTBLANK(K17)=0,K17,"Cash/UPI") -> NetBanking
A18: TXN1016 | B18: 45674 | C18: April | D18: Nikita Roy | E18: 29 | F18: Delhi | G18: Salary | H18: 62000 | I18: Groceries | J18: 5900 | K18: UPI | L18: 12000 | M18: 3000 | N18: 725 | O18: Good | P18: =IF(COUNTBLANK(#REF!)=0,#REF!,"Unknown") -> Delhi | Q18: =IF(COUNTBLANK(#REF!)=0,#REF!,"Unknown") -> Salary | R18: =IF(COUNTBLANK(#REF!)=0,#REF!,"Unknown") -> Groceries | S18: =IF(COUNTBLANK(#REF!)=0,#REF!,0) -> 3000 | T18: =IF(COUNTBLANK(K18)=0,K18,"Cash/UPI") -> UPI
A19: TXN1017 | B19: 45675 | C19: May | D19: Manish Yadav | E19: 35 | F19: Mumbai | G19: Salary | H19: 81000 | I19: Transport | J19: 4100 | K19: Cash | L19: 16000 | M19: 9000 | N19: 710 | O19: Stable | P19: =IF(COUNTBLANK(#REF!)=0,#REF!,"Unknown") -> Mumbai | Q19: =IF(COUNTBLANK(#REF!)=0,#REF!,"Unknown") -> Salary | R19: =IF(COUNTBLANK(#REF!)=0,#REF!,"Unknown") -> Transport | S19: =IF(COUNTBLANK(#REF!)=0,#REF!,0) -> 9000 | T19: =IF(COUNTBLANK(K19)=0,K19,"Cash/UPI") -> Cash
A20: TXN1018 | B20: 45676 | C20: June | D20: Simran Kaur | E20: 27 | F20: Chandigarh | G20: Freelancing | H20: 56000 | J20: 9700 | K20: Card | L20: 8500 | N20: 699 | O20: Average | P20: =IF(COUNTBLANK(#REF!)=0,#REF!,"Unknown") -> Chandigarh | Q20: =IF(COUNTBLANK(#REF!)=0,#REF!,"Unknown") -> Freelancing | R20: =IF(COUNTBLANK(#REF!)=0,#REF!,"Unknown") -> Unknown | S20: =IF(COUNTBLANK(#REF!)=0,#REF!,0) -> 0 | T20: =IF(COUNTBLANK(K20)=0,K20,"Cash/UPI") -> Card
A21: TXN1019 | B21: 45677 | C21: July | D21: Raj Malhotra | E21: 41 | F21: Delhi | G21: Business | H21: 145000 | I21: Utilities | J21: 7800 | K21: Cheque | L21: 42000 | M21: 25000 | N21: 805 | O21: Excellent | P21: =IF(COUNTBLANK(#REF!)=0,#REF!,"Unknown") -> Delhi | Q21: =IF(COUNTBLANK(#REF!)=0,#REF!,"Unknown") -> Business | R21: =IF(COUNTBLANK(#REF!)=0,#REF!,"Unknown") -> Utilities | S21: =IF(COUNTBLANK(#REF!)=0,#REF!,0) -> 25000 | T21: =IF(COUNTBLANK(K21)=0,K21,"Cash/UPI") -> Cheque
A22: TXN1020 | B22: 45678 | C22: August | D22: Pooja Mehta | E22: 32 | F22: Ahmedabad | G22: Salary | H22: 69000 | I22: Food | J22: 6300 | K22: UPI | L22: 10000 | M22: 4500 | N22: 730 | O22: Good | P22: =IF(COUNTBLANK(#REF!)=0,#REF!,"Unknown") -> Ahmedabad | Q22: =IF(COUNTBLANK(#REF!)=0,#REF!,"Unknown") -> Salary | R22: =IF(COUNTBLANK(#REF!)=0,#REF!,"Unknown") -> Food | S22: =IF(COUNTBLANK(#REF!)=0,#REF!,0) -> 4500 | T22: =IF(COUNTBLANK(K22)=0,K22,"Cash/UPI") -> UPI
A23: TXN1021 | B23: 45679 | C23: September | D23: Deepak Kumar | E23: 37 | F23: Patna | G23: Salary | H23: 57000 | I23: Rent | J23: 16000 | K23: Cash | L23: 6000 | M23: 5500 | N23: 670 | O23: Risky | P23: =IF(COUNTBLANK(#REF!)=0,#REF!,"Unknown") -> Patna | Q23: =IF(COUNTBLANK(#REF!)=0,#REF!,"Unknown") -> Salary | R23: =IF(COUNTBLANK(#REF!)=0,#REF!,"Unknown") -> Rent | S23: =IF(COUNTBLANK(#REF!)=0,#REF!,0) -> 5500 | T23: =IF(COUNTBLANK(K23)=0,K23,"Cash/UPI") -> Cash
A24: TXN1022 | B24: 45680 | C24: October | D24: Tanvi Shah | E24: 26 | F24: Surat | G24: Freelancing | H24: 52000 | I24: Shopping | J24: 7600 | K24: Card | L24: 9000 | N24: 715 | O24: Stable | P24: =IF(COUNTBLANK(#REF!)=0,#REF!,"Unknown") -> Surat | Q24: =IF(COUNTBLANK(#REF!)=0,#REF!,"Unknown") -> Freelancing | R24: =IF(COUNTBLANK(#REF!)=0,#REF!,"Unknown") -> Shopping | S24: =IF(COUNTBLANK(#REF!)=0,#REF!,0) -> 0 | T24: =IF(COUNTBLANK(K24)=0,K24,"Cash/UPI") -> Card
A25: TXN1023 | B25: 45681 | C25: November | D25: Ritesh Verma | E25: 40 | H25: 125000 | I25: Investment | J25: 28000 | K25: NetBanking | L25: 37000 | M25: 12000 | N25: 798 | O25: Excellent | P25: =IF(COUNTBLANK(#REF!)=0,#REF!,"Unknown") -> Unknown | Q25: =IF(COUNTBLANK(#REF!)=0,#REF!,"Unknown") -> Unknown | R25: =IF(COUNTBLANK(#REF!)=0,#REF!,"Unknown") -> Investment | S25: =IF(COUNTBLANK(#REF!)=0,#REF!,0) -> 12000 | T25: =IF(COUNTBLANK(K25)=0,K25,"Cash/UPI") -> NetBanking
A26: TXN1024 | B26: 45682 | C26: December | D26: Ananya Ghosh | E26: 31 | F26: Kolkata | G26: Salary | H26: 74000 | I26: Education | J26: 5300 | K26: UPI | L26: 15000 | M26: 5000 | N26: 750 | O26: Good | P26: =IF(COUNTBLANK(#REF!)=0,#REF!,"Unknown") -> Kolkata | Q26: =IF(COUNTBLANK(#REF!)=0,#REF!,"Unknown") -> Salary | R26: =IF(COUNTBLANK(#REF!)=0,#REF!,"Unknown") -> Education | S26: =IF(COUNTBLANK(#REF!)=0,#REF!,0) -> 5000 | T26: =IF(COUNTBLANK(K26)=0,K26,"Cash/UPI") -> UPI
A27: TXN1025 | B27: 45683 | C27: January | D27: Kunal Sharma | E27: 28 | F27: Delhi | G27: Salary | H27: 63000 | J27: 8600 | K27: Card | L27: 11000 | M27: 3500 | N27: 721 | O27: Stable | P27: =IF(COUNTBLANK(#REF!)=0,#REF!,"Unknown") -> Delhi | Q27: =IF(COUNTBLANK(#REF!)=0,#REF!,"Unknown") -> Salary | R27: =IF(COUNTBLANK(#REF!)=0,#REF!,"Unknown") -> Unknown | S27: =IF(COUNTBLANK(#REF!)=0,#REF!,0) -> 3500 | T27: =IF(COUNTBLANK(K27)=0,K27,"Cash/UPI") -> Card
A28: TXN1075 | B28: 45733 | C28: February | D28: Amit Bose | E28: 36 | F28: Kolkata | G28: Salary | H28: 81000 | I28: Travel | J28: 9400 | K28: UPI | L28: 17000 | M28: 8500 | N28: 743 | O28: Good | P28: =IF(COUNTBLANK(#REF!)=0,#REF!,"Unknown") -> Kolkata | Q28: =IF(COUNTBLANK(#REF!)=0,#REF!,"Unknown") -> Salary | R28: =IF(COUNTBLANK(#REF!)=0,#REF!,"Unknown") -> Travel | S28: =IF(COUNTBLANK(#REF!)=0,#REF!,0) -> 8500 | T28: =IF(COUNTBLANK(K28)=0,K28,"Cash/UPI") -> UPI
A29: TXN1076 | B29: 45734 | C29: March | D29: Sonia Jain | E29: 27 | F29: Pune | G29: Freelancing | H29: 55000 | I29: Food | J29: 5200 | K29: Card | L29: 8000 | N29: 701 | O29: Stable | P29: =IF(COUNTBLANK(#REF!)=0,#REF!,"Unknown") -> Pune | Q29: =IF(COUNTBLANK(#REF!)=0,#REF!,"Unknown") -> Freelancing | R29: =IF(COUNTBLANK(#REF!)=0,#REF!,"Unknown") -> Food | S29: =IF(COUNTBLANK(#REF!)=0,#REF!,0) -> 0 | T29: =IF(COUNTBLANK(K29)=0,K29,"Cash/UPI") -> Card
A30: TXN1077 | B30: 45735 | C30: April | D30: Harsh Vardhan | E30: 43 | F30: Delhi | G30: Business | H30: 149000 | I30: Investment | J30: 41000 | K30: Cheque | L30: 50000 | M30: 23000 | N30: 815 | O30: Excellent | P30: =IF(COUNTBLANK(#REF!)=0,#REF!,"Unknown") -> Delhi | Q30: =IF(COUNTBLANK(#REF!)=0,#REF!,"Unknown") -> Business | R30: =IF(COUNTBLANK(#REF!)=0,#REF!,"Unknown") -> Investment | S30: =IF(COUNTBLANK(#REF!)=0,#REF!,0) -> 23000 | T30: =IF(COUNTBLANK(K30)=0,K30,"Cash/UPI") -> Cheque
A31: TXN1078 | B31: 45736 | C31: May | D31: Ankita Sen | E31: 30 | F31: Kolkata | G31: Salary | H31: 72000 | I31: Utilities | J31: 6300 | K31: UPI | L31: 14500 | M31: 3500 | N31: 735 | O31: Good | P31: =IF(COUNTBLANK(#REF!)=0,#REF!,"Unknown") -> Kolkata | Q31: =IF(COUNTBLANK(#REF!)=0,#REF!,"Unknown") -> Salary | R31: =IF(COUNTBLANK(#REF!)=0,#REF!,"Unknown") -> Utilities | S31: =IF(COUNTBLANK(#REF!)=0,#REF!,0) -> 3500 | T31: =IF(COUNTBLANK(K31)=0,K31,"Cash/UPI") -> UPI
A32: TXN1079 | B32: 45737 | C32: June | D32: Rohan Sharma | E32: 28 | F32: Delhi | G32: Salary | H32: 65000 | I32: Transport | J32: 4800 | K32: Cash | L32: 10000 | M32: 4000 | N32: 712 | O32: Stable | P32: =IF(COUNTBLANK(#REF!)=0,#REF!,"Unknown") -> Delhi | Q32: =IF(COUNTBLANK(#REF!)=0,#REF!,"Unknown") -> Salary | R32: =IF(COUNTBLANK(#REF!)=0,#REF!,"Unknown") -> Transport | S32: =IF(COUNTBLANK(#REF!)=0,#REF!,0) -> 4000 | T32: =IF(COUNTBLANK(K32)=0,K32,"Cash/UPI") -> Cash
A33: TXN1080 | B33: 45738 | C33: July | D33: Priya Roy | E33: 25 | F33: Kolkata | G33: Freelancing | H33: 50000 | I33: Shopping | J33: 8100 | K33: Card | L33: 6000 | N33: 689 | O33: Average | P33: =IF(COUNTBLANK(#REF!)=0,#REF!,"Unknown") -> Kolkata | Q33: =IF(COUNTBLANK(#REF!)=0,#REF!,"Unknown") -> Freelancing | R33: =IF(COUNTBLANK(#REF!)=0,#REF!,"Unknown") -> Shopping | S33: =IF(COUNTBLANK(#REF!)=0,#REF!,0) -> 0 | T33: =IF(COUNTBLANK(K33)=0,K33,"Cash/UPI") -> Card
A34: TXN1081 | B34: 45739 | C34: August | D34: Abhishek Jain | E34: 40 | F34: Mumbai | H34: 137000 | I34: Rent | J34: 33000 | L34: 41000 | M34: 17000 | N34: 799 | O34: Excellent | P34: =IF(COUNTBLANK(#REF!)=0,#REF!,"Unknown") -> Mumbai | Q34: =IF(COUNTBLANK(#REF!)=0,#REF!,"Unknown") -> Unknown | R34: =IF(COUNTBLANK(#REF!)=0,#REF!,"Unknown") -> Rent | S34: =IF(COUNTBLANK(#REF!)=0,#REF!,0) -> 17000 | T34: =IF(COUNTBLANK(K34)=0,K34,"Cash/UPI") -> Cash/UPI
A35: TXN1082 | B35: 45740 | C35: September | D35: Tania Das | E35: 31 | F35: Kolkata | G35: Salary | H35: 70000 | I35: Healthcare | J35: 4600 | K35: UPI | L35: 13000 | M35: 3000 | N35: 732 | O35: Good | P35: =IF(COUNTBLANK(#REF!)=0,#REF!,"Unknown") -> Kolkata | Q35: =IF(COUNTBLANK(#REF!)=0,#REF!,"Unknown") -> Salary | R35: =IF(COUNTBLANK(#REF!)=0,#REF!,"Unknown") -> Healthcare | S35: =IF(COUNTBLANK(#REF!)=0,#REF!,0) -> 3000 | T35: =IF(COUNTBLANK(K35)=0,K35,"Cash/UPI") -> UPI
A36: TXN1083 | B36: 45741 | C36: October | D36: Manish Roy | E36: 35 | F36: Delhi | G36: Salary | H36: 83000 | I36: Travel | J36: 10200 | K36: Card | L36: 18000 | M36: 9500 | N36: 747 | O36: Good | P36: =IF(COUNTBLANK(#REF!)=0,#REF!,"Unknown") -> Delhi | Q36: =IF(COUNTBLANK(#REF!)=0,#REF!,"Unknown") -> Salary | R36: =IF(COUNTBLANK(#REF!)=0,#REF!,"Unknown") -> Travel | S36: =IF(COUNTBLANK(#REF!)=0,#REF!,0) -> 9500 | T36: =IF(COUNTBLANK(K36)=0,K36,"Cash/UPI") -> Card
A37: TXN1084 | B37: 45742 | C37: November | D37: Sweta Kapoor | E37: 26 | F37: Pune | G37: Freelancing | H37: 53000 | I37: Entertainment | J37: 4100 | K37: Cash | L37: 7000 | N37: 694 | O37: Average | P37: =IF(COUNTBLANK(#REF!)=0,#REF!,"Unknown") -> Pune | Q37: =IF(COUNTBLANK(#REF!)=0,#REF!,"Unknown") -> Freelancing | R37: =IF(COUNTBLANK(#REF!)=0,#REF!,"Unknown") -> Entertainment | S37: =IF(COUNTBLANK(#REF!)=0,#REF!,0) -> 0 | T37: =IF(COUNTBLANK(K37)=0,K37,"Cash/UPI") -> Cash
A38: TXN1085 | B38: 45743 | C38: December | D38: Kunal Verma | E38: 42 | F38: Ahmedabad | G38: Business | H38: 144000 | I38: Investment | J38: 37000 | K38: Cheque | L38: 46000 | M38: 21000 | N38: 810 | O38: Excellent | P38: =IF(COUNTBLANK(#REF!)=0,#REF!,"Unknown") -> Ahmedabad | Q38: =IF(COUNTBLANK(#REF!)=0,#REF!,"Unknown") -> Business | R38: =IF(COUNTBLANK(#REF!)=0,#REF!,"Unknown") -> Investment | S38: =IF(COUNTBLANK(#REF!)=0,#REF!,0) -> 21000 | T38: =IF(COUNTBLANK(K38)=0,K38,"Cash/UPI") -> Cheque
A39: TXN1086 | B39: 45744 | C39: January | D39: Megha Roy | E39: 29 | F39: Kolkata | G39: Salary | H39: 69000 | I39: Groceries | J39: 6200 | K39: UPI | L39: 12500 | M39: 3000 | N39: 728 | O39: Good | P39: =IF(COUNTBLANK(#REF!)=0,#REF!,"Unknown") -> Kolkata | Q39: =IF(COUNTBLANK(#REF!)=0,#REF!,"Unknown") -> Salary | R39: =IF(COUNTBLANK(#REF!)=0,#REF!,"Unknown") -> Groceries | S39: =IF(COUNTBLANK(#REF!)=0,#REF!,0) -> 3000 | T39: =IF(COUNTBLANK(K39)=0,K39,"Cash/UPI") -> UPI
A40: TXN1087 | B40: 45745 | C40: February | D40: Rajat Das | E40: 33 | G40: Salary | H40: 78000 | I40: Rent | J40: 22000 | K40: Card | L40: 15000 | M40: 7000 | N40: 739 | O40: Good | P40: =IF(COUNTBLANK(#REF!)=0,#REF!,"Unknown") -> Unknown | Q40: =IF(COUNTBLANK(#REF!)=0,#REF!,"Unknown") -> Salary | R40: =IF(COUNTBLANK(#REF!)=0,#REF!,"Unknown") -> Rent | S40: =IF(COUNTBLANK(#REF!)=0,#REF!,0) -> 7000 | T40: =IF(COUNTBLANK(K40)=0,K40,"Cash/UPI") -> Card
...

Sheet Cleaned Data
A1: CLEANED DATA
A2: Id | B2: Date | C2: Month | D2: Person Name | E2: Age | F2: City | G2: Income Source | H2: Monthly Income | I2: Expense Category | J2: Expense Amount | K2: Payment Method | L2: Savings | M2: Loan EMI | N2: Credit Score | O2: Financial Status
A3: TXN1001 | B3: 45659 | C3: January | D3: Rahul Sen | E3: 29 | F3: =IF(COUNTBLANK(#REF!)=0,#REF!,"Unknown") -> Kolkata | G3: =IF(COUNTBLANK(#REF!)=0,#REF!,"Unknown") -> Salary | H3: 65000 | I3: =IF(COUNTBLANK(#REF!)=0,#REF!,"Unknown") -> Rent | J3: 18000 | K3: UPI | L3: 12000 | M3: =IF(COUNTBLANK(#REF!)=0,#REF!,0) -> 5000 | N3: 742 | O3: Stable
A4: TXN1002 | B4: 45660 | C4: February | D4: Priya Das | E4: 34 | F4: =IF(COUNTBLANK(#REF!)=0,#REF!,"Unknown") -> Mumbai | G4: =IF(COUNTBLANK(#REF!)=0,#REF!,"Unknown") -> Freelancing | H4: 72000 | I4: =IF(COUNTBLANK(#REF!)=0,#REF!,"Unknown") -> Groceries | J4: 6500 | K4: Card | L4: 15000 | M4: =IF(COUNTBLANK(#REF!)=0,#REF!,0) -> 0 | N4: 788 | O4: Good
A5: TXN1003 | B5: 45661 | C5: March | D5: Ankit Roy | E5: 26 | F5: =IF(COUNTBLANK(#REF!)=0,#REF!,"Unknown") -> Unknown | G5: =IF(COUNTBLANK(#REF!)=0,#REF!,"Unknown") -> Salary | H5: 54000 | I5: =IF(COUNTBLANK(#REF!)=0,#REF!,"Unknown") -> Unknown | J5: 3200 | K5: Cash | L5: 8000 | M5: =IF(COUNTBLANK(#REF!)=0,#REF!,0) -> 2500 | N5: 689 | O5: Average
A6: TXN1004 | B6: 45662 | C6: April | D6: Sneha Paul | E6: 31 | F6: =IF(COUNTBLANK(#REF!)=0,#REF!,"Unknown") -> Bangalore | G6: =IF(COUNTBLANK(#REF!)=0,#REF!,"Unknown") -> Business | H6: 98000 | I6: =IF(COUNTBLANK(#REF!)=0,#REF!,"Unknown") -> Utilities | J6: 5400 | K6: NetBanking | L6: 25000 | M6: =IF(COUNTBLANK(#REF!)=0,#REF!,0) -> 8000 | N6: 801 | O6: Excellent
A7: TXN1005 | B7: 45663 | C7: May | D7: Rohan Mitra | E7: 38 | F7: =IF(COUNTBLANK(#REF!)=0,#REF!,"Unknown") -> Hyderabad | G7: =IF(COUNTBLANK(#REF!)=0,#REF!,"Unknown") -> Salary | H7: 85000 | I7: =IF(COUNTBLANK(#REF!)=0,#REF!,"Unknown") -> Entertainment | J7: 7600 | K7: Card | L7: 10000 | M7: =IF(COUNTBLANK(#REF!)=0,#REF!,0) -> 12000 | N7: 655 | O7: Risky
A8: TXN1006 | B8: 45664 | C8: June | D8: Aditi Sharma | E8: 27 | F8: =IF(COUNTBLANK(#REF!)=0,#REF!,"Unknown") -> Pune | G8: =IF(COUNTBLANK(#REF!)=0,#REF!,"Unknown") -> Salary | H8: 61000 | I8: =IF(COUNTBLANK(#REF!)=0,#REF!,"Unknown") -> Healthcare | J8: 2400 | K8: UPI | L8: 17000 | M8: =IF(COUNTBLANK(#REF!)=0,#REF!,0) -> 0 | N8: 771 | O8: Good
A9: TXN1007 | B9: 45665 | C9: July | D9: Karan Singh | E9: 42 | F9: =IF(COUNTBLANK(#REF!)=0,#REF!,"Unknown") -> Chennai | G9: =IF(COUNTBLANK(#REF!)=0,#REF!,"Unknown") -> Business | H9: 120000 | I9: =IF(COUNTBLANK(#REF!)=0,#REF!,"Unknown") -> Rent | J9: 25000 | K9: Cheque | L9: 35000 | M9: =IF(COUNTBLANK(#REF!)=0,#REF!,0) -> 18000 | N9: 720 | O9: Stable
A10: TXN1008 | B10: 45666 | C10: August | D10: Megha Dutta | E10: 24 | F10: =IF(COUNTBLANK(#REF!)=0,#REF!,"Unknown") -> Kolkata | G10: =IF(COUNTBLANK(#REF!)=0,#REF!,"Unknown") -> Internship | H10: 28000 | I10: =IF(COUNTBLANK(#REF!)=0,#REF!,"Unknown") -> Education | J10: 4500 | K10: UPI | L10: 5000 | M10: =IF(COUNTBLANK(#REF!)=0,#REF!,0) -> 0 | N10: 690 | O10: Average
A11: TXN1009 | B11: 45667 | C11: September | D11: Arjun Nair | E11: 36 | F11: =IF(COUNTBLANK(#REF!)=0,#REF!,"Unknown") -> Kochi | G11: =IF(COUNTBLANK(#REF!)=0,#REF!,"Unknown") -> Salary | H11: 76000 | I11: =IF(COUNTBLANK(#REF!)=0,#REF!,"Unknown") -> Unknown | J11: 8200 | K11: Card | L11: 14000 | M11: =IF(COUNTBLANK(#REF!)=0,#REF!,0) -> 7000 | N11: 745 | O11: Stable
A12: TXN1010 | B12: 45668 | C12: October | D12: Neha Kapoor | E12: 30 | F12: =IF(COUNTBLANK(#REF!)=0,#REF!,"Unknown") -> Jaipur | G12: =IF(COUNTBLANK(#REF!)=0,#REF!,"Unknown") -> Freelancing | H12: 68000 | I12: =IF(COUNTBLANK(#REF!)=0,#REF!,"Unknown") -> Shopping | J12: 9200 | K12: UPI | L12: 11000 | M12: =IF(COUNTBLANK(#REF!)=0,#REF!,0) -> 3000 | N12: 732 | O12: Good
A13: TXN1011 | B13: 45669 | C13: November | D13: Vikram Bose | E13: 45 | F13: =IF(COUNTBLANK(#REF!)=0,#REF!,"Unknown") -> Kolkata | G13: =IF(COUNTBLANK(#REF!)=0,#REF!,"Unknown") -> Business | H13: 150000 | I13: =IF(COUNTBLANK(#REF!)=0,#REF!,"Unknown") -> Investment | J13: 35000 | K13: NetBanking | L13: 40000 | M13: =IF(COUNTBLANK(#REF!)=0,#REF!,0) -> 20000 | N13: 810 | O13: Excellent
A14: TXN1012 | B14: 45670 | C14: December | D14: Isha Jain | E14: 28 | F14: =IF(COUNTBLANK(#REF!)=0,#REF!,"Unknown") -> Delhi | G14: =IF(COUNTBLANK(#REF!)=0,#REF!,"Unknown") -> Unknown | H14: 59000 | I14: =IF(COUNTBLANK(#REF!)=0,#REF!,"Unknown") -> Food | J14: 5800 | K14: Cash/UPI | L14: 9000 | M14: =IF(COUNTBLANK(#REF!)=0,#REF!,0) -> 2500 | N14: 704 | O14: Stable
... A100: TXN1072 | B100: 45730 | C100: February | D100: Payal Roy | E100: 24 | F100: =IF(COUNTBLANK(#REF!)=0,#REF!,"Unknown") -> Unknown | G100: =IF(COUNTBLANK(#REF!)=0,#REF!,"Unknown") -> Unknown | H100: 32000 | I100: =IF(COUNTBLANK(#REF!)=0,#REF!,"Unknown") -> Unknown | J100: 3900 | K100: Cash/UPI | L100: 3500 | M100: =IF(COUNTBLANK(#REF!)=0,#REF!,0) -> 0 | N100: 678 | O100: Average

Sheet Income Sheet
A1: MONTHLY INCOME ANALYSIS
A2: Date | B2: Id | C2: Income Source | D2: Month | E2: Monthly Income | F2: Payment Method | H2: Total Income View
A3: 45659 | B3: TXN1001 | C3: =IF(COUNTBLANK(#REF!)=0,#REF!,"Unknown") -> Salary | D3: January | E3: 65000 | F3: UPI | H3: Total Income | I3: =SUM(E3:E100) -> 7871000
A4: 45660 | B4: TXN1002 | C4: =IF(COUNTBLANK(#REF!)=0,#REF!,"Unknown") -> Freelancing | D4: February | E4: 72000 | F4: Card | H4: Average Income | I4: =AVERAGE(E3:E100) -> 80316.327
A5: 45661 | B5: TXN1003 | C5: =IF(COUNTBLANK(#REF!)=0,#REF!,"Unknown") -> Salary | D5: March | E5: 54000 | F5: Cash | H5: Highest Income | I5: =MAX(E3:E100) -> 158000
A6: 45662 | B6: TXN1004 | C6: =IF(COUNTBLANK(#REF!)=0,#REF!,"Unknown") -> Business | D6: April | E6: 98000 | F6: NetBanking | H6: Lowest Income | I6: =MIN(E3:E100) -> 27000
A7: 45663 | B7: TXN1005 | C7: =IF(COUNTBLANK(#REF!)=0,#REF!,"Unknown") -> Salary | D7: May | E7: 85000 | F7: Card
A8: 45664 | B8: TXN1006 | C8: =IF(COUNTBLANK(#REF!)=0,#REF!,"Unknown") -> Salary | D8: June | E8: 61000 | F8: UPI
A9: 45665 | B9: TXN1007 | C9: =IF(COUNTBLANK(#REF!)=0,#REF!,"Unknown") -> Business | D9: July | E9: 120000 | F9: Cheque
A10: 45666 | B10: TXN1008 | C10: =IF(COUNTBLANK(#REF!)=0,#REF!,"Unknown") -> Internship | D10: August | E10: 28000 | F10: UPI | H10: Monthly Income
A11: 45667 | B11: TXN1009 | C11: =IF(COUNTBLANK(#REF!)=0,#REF!,"Unknown") -> Salary | D11: September | E11: 76000 | F11: Card | H11: January | I11: =SUMIF($D:$D,"January",$E:$E) -> 605000
A12: 45668 | B12: TXN1010 | C12: =IF(COUNTBLANK(#REF!)=0,#REF!,"Unknown") -> Freelancing | D12: October | E12: 68000 | F12: UPI | H12: February | I12: =SUMIF($D:$D,"February",$E:$E) -> 681000
A13: 45669 | B13: TXN1011 | C13: =IF(COUNTBLANK(#REF!)=0,#REF!,"Unknown") -> Business | D13: November | E13: 150000 | F13: NetBanking | H13: March | I13: =SUMIF($D:$D,"March",$E:$E) -> 570000
A14: 45670 | B14: TXN1012 | C14: =IF(COUNTBLANK(#REF!)=0,#REF!,"Unknown") -> Unknown | D14: December | E14: 59000 | F14: Cash/UPI | H14: April | I14: =SUMIF($D:$D,"April",$E:$E) -> 817000
A15: 45671 | B15: TXN1013 | C15: =IF(COUNTBLANK(#REF!)=0,#REF!,"Unknown") -> Salary | D15: January | E15: 71000 | F15: UPI | H15: May | I15: =SUMIF($D:$D,"May",$E:$E) -> 552000
A16: 45672 | B16: TXN1014 | C16: =IF(COUNTBLANK(#REF!)=0,#REF!,"Unknown") -> Freelancing | D16: February | E16: 47000 | F16: Card | H16: June | I16: =SUMIF($D:$D,"June",$E:$E) -> 639000
A17: 45673 | B17: TXN1015 | C17: =IF(COUNTBLANK(#REF!)=0,#REF!,"Unknown") -> Business | D17: March | E17: 132000 | F17: NetBanking | H17: July | I17: =SUMIF($D:$D,"July",$E:$E) -> 731000
A18: 45674 | B18: TXN1016 | C18: =IF(COUNTBLANK(#REF!)=0,#REF!,"Unknown") -> Salary | D18: April | E18: 62000 | F18: UPI | H18: August | I18: =SUMIF($D:$D,"August",$E:$E) -> 630000
A19: 45675 | B19: TXN1017 | C19: =IF(COUNTBLANK(#REF!)=0,#REF!,"Unknown") -> Salary | D19: May | E19: 81000 | F19: Cash | H19: September | I19: =SUMIF($D:$D,"September",$E:$E) -> 661000
A20: 45676 | B20: TXN1018 | C20: =IF(COUNTBLANK(#REF!)=0,#REF!,"Unknown") -> Freelancing | D20: June | E20: 56000 | F20: Card | H20: October | I20: =SUMIF($D:$D,"October",$E:$E) -> 465000
A21: 45677 | B21: TXN1019 | C21: =IF(COUNTBLANK(#REF!)=0,#REF!,"Unknown") -> Business | D21: July | E21: 145000 | F21: Cheque | H21: November | I21: =SUMIF($D:$D,"November",$E:$E) -> 825000
A22: 45678 | B22: TXN1020 | C22: =IF(COUNTBLANK(#REF!)=0,#REF!,"Unknown") -> Salary | D22: August | E22: 69000 | F22: UPI | H22: December | I22: =SUMIF($D:$D,"December",$E:$E) -> 695000
A23: 45679 | B23: TXN1021 | C23: =IF(COUNTBLANK(#REF!)=0,#REF!,"Unknown") -> Salary | D23: September | E23: 57000 | F23: Cash
A24: 45680 | B24: TXN1022 | C24: =IF(COUNTBLANK(#REF!)=0,#REF!,"Unknown") -> Freelancing | D24: October | E24: 52000 | F24: Card
A25: 45681 | B25: TXN1023 | C25: =IF(COUNTBLANK(#REF!)=0,#REF!,"Unknown") -> Unknown | D25: November | E25: 125000 | F25: NetBanking
A26: 45682 | B26: TXN1024 | C26: =IF(COUNTBLANK(#REF!)=0,#REF!,"Unknown") -> Salary | D26: December | E26: 74000 | F26: UPI
A27: 45683 | B27: TXN1025 | C27: =IF(COUNTBLANK(#REF!)=0,#REF!,"Unknown") -> Salary | D27: January | E27: 63000 | F27: Card
A28: 45733 | B28: TXN1075 | C28: =IF(COUNTBLANK(#REF!)=0,#REF!,"Unknown") -> Salary | D28: February | E28: 81000 | F28: UPI
A29: 45734 | B29: TXN1076 | C29: =IF(COUNTBLANK(#REF!)=0,#REF!,"Unknown") -> Freelancing | D29: March | E29: 55000 | F29: Card
A30: 45735 | B30: TXN1077 | C30: =IF(COUNTBLANK(#REF!)=0,#REF!,"Unknown") -> Business | D30: April | E30: 149000 | F30: Cheque
A31: 45736 | B31: TXN1078 | C31: =IF(COUNTBLANK(#REF!)=0,#REF!,"Unknown") -> Salary | D31: May | E31: 72000 | F31: UPI
A32: 45737 | B32: TXN1079 | C32: =IF(COUNTBLANK(#REF!)=0,#REF!,"Unknown") -> Salary | D32: June | E32: 65000 | F32: Cash
A33: 45738 | B33: TXN1080 | C33: =IF(COUNTBLANK(#REF!)=0,#REF!,"Unknown") -> Freelancing | D33: July | E33: 50000 | F33: Card
A34: 45739 | B34: TXN1081 | C34: =IF(COUNTBLANK(#REF!)=0,#REF!,"Unknown") -> Unknown | D34: August | E34: 137000 | F34: Cash/UPI
... A100: 45730 | B100: TXN1072 | C100: =IF(COUNTBLANK(#REF!)=0,#REF!,"Unknown") -> Unknown | D100: February | E100: 32000 | F100: Cash/UPI
M101: {=M4:M101} -> 0

Sheet Income Pivot Table
A1: MONTHLY INCOME TREND
A3: Row Labels | B3: Sum of Monthly Income
A4: January | B4: 605000
A5: February | B5: 681000
A6: March | B6: 570000
A7: April | B7: 817000
A8: May | B8: 552000
A9: June | B9: 639000
A10: July | B10: 731000
A11: August | B11: 630000
A12: September | B12: 661000
A13: October | B13: 465000
A14: November | B14: 825000
A15: December | B15: 695000
A16: Grand Total | B16: 7871000

Sheet Expense Sheet
A1: MONTHLY EXPENSE ANALYSIS
A2: Date | B2: Month | C2: Expense Category | D2: Expense Amount | E2: Payment Method | G2: Expense View | J2: Payment Method Filter | M2: Mode
A3: 45659 | B3: January | C3: =IF(COUNTBLANK(#REF!)=0,#REF!,"Unknown") -> Rent | D3: 18000 | E3: UPI | G3: Expence Category | H3: Total Expense | J3: Select Method | K3: Cash | M3: UPI
A4: 45660 | B4: February | C4: =IF(COUNTBLANK(#REF!)=0,#REF!,"Unknown") -> Groceries | D4: 6500 | E4: Card | G4: Rent | H4: =SUMIF($C:$C,G4,$D:$D) -> 327000 | J4: Total Expense | K4: =SUMIF($E:$E,K3,$D:$D) -> 68300 | M4: Cash
A5: 45661 | B5: March | C5: =IF(COUNTBLANK(#REF!)=0,#REF!,"Unknown") -> Unknown | D5: 3200 | E5: Cash | G5: Food | H5: =SUMIF($C:$C,G5,$D:$D) -> 41300 | M5: NetBanking
A6: 45662 | B6: April | C6: =IF(COUNTBLANK(#REF!)=0,#REF!,"Unknown") -> Utilities | D6: 5400 | E6: NetBanking | G6: Healthcare | H6: =SUMIF($C:$C,G6,$D:$D) -> 56000 | M6: Cheque
A7: 45663 | B7: May | C7: =IF(COUNTBLANK(#REF!)=0,#REF!,"Unknown") -> Entertainment | D7: 7600 | E7: Card | G7: Shopping | H7: =SUMIF($C:$C,G7,$D:$D) -> 78900
A8: 45664 | B8: June | C8: =IF(COUNTBLANK(#REF!)=0,#REF!,"Unknown") -> Healthcare | D8: 2400 | E8: UPI
A9: 45665 | B9: July | C9: =IF(COUNTBLANK(#REF!)=0,#REF!,"Unknown") -> Rent | D9: 25000 | E9: Cheque | G9: Monthly Expenses | J9: Month Filter
A10: 45666 | B10: August | C10: =IF(COUNTBLANK(#REF!)=0,#REF!,"Unknown") -> Education | D10: 4500 | E10: UPI | G10: January | H10: =SUMIF($B:$B,G10,$D:$D) -> 112500 | J10: Select Month | K10: January
A11: 45667 | B11: September | C11: =IF(COUNTBLANK(#REF!)=0,#REF!,"Unknown") -> Unknown | D11: 8200 | E11: Card | G11: February | H11: =SUMIF($B:$B,G11,$D:$D) -> 99100 | J11: Total Expense | K11: =SUMIF($B:$B,K10,$D:$D) -> 112500
A12: 45668 | B12: October | C12: =IF(COUNTBLANK(#REF!)=0,#REF!,"Unknown") -> Shopping | D12: 9200 | E12: UPI | G12: March | H12: =SUMIF($B:$B,G12,$D:$D) -> 71700
A13: 45669 | B13: November | C13: =IF(COUNTBLANK(#REF!)=0,#REF!,"Unknown") -> Investment | D13: 35000 | E13: NetBanking | G13: April | H13: =SUMIF($B:$B,G13,$D:$D) -> 81700
A14: 45670 | B14: December | C14: =IF(COUNTBLANK(#REF!)=0,#REF!,"Unknown") -> Food | D14: 5800 | E14: Cash/UPI | G14: May | H14: =SUMIF($B:$B,G14,$D:$D) -> 50100
A15: 45671 | B15: January | C15: =IF(COUNTBLANK(#REF!)=0,#REF!,"Unknown") -> Rent | D15: 21000 | E15: UPI | G15: June | H15: =SUMIF($B:$B,G15,$D:$D) -> 109500
A16: 45672 | B16: February | C16: =IF(COUNTBLANK(#REF!)=0,#REF!,"Unknown") -> Entertainment | D16: 4200 | E16: Card | G16: July | H16: =SUMIF($B:$B,G16,$D:$D) -> 103300
A17: 45673 | B17: March | C17: =IF(COUNTBLANK(#REF!)=0,#REF!,"Unknown") -> Healthcare | D17: 6800 | E17: NetBanking | G17: August | H17: =SUMIF($B:$B,G17,$D:$D) -> 118900
A18: 45674 | B18: April | C18: =IF(COUNTBLANK(#REF!)=0,#REF!,"Unknown") -> Groceries | D18: 5900 | E18: UPI | G18: September | H18: =SUMIF($B:$B,G18,$D:$D) -> 95000
A19: 45675 | B19: May | C19: =IF(COUNTBLANK(#REF!)=0,#REF!,"Unknown") -> Transport | D19: 4100 | E19: Cash | G19: October | H19: =SUMIF($B:$B,G19,$D:$D) -> 67500
A20: 45676 | B20: June | C20: =IF(COUNTBLANK(#REF!)=0,#REF!,"Unknown") -> Unknown | D20: 9700 | E20: Card | G20: November | H20: =SUMIF($B:$B,G20,$D:$D) -> 148300
A21: 45677 | B21: July | C21: =IF(COUNTBLANK(#REF!)=0,#REF!,"Unknown") -> Utilities | D21: 7800 | E21: Cheque | G21: December | H21: =SUMIF($B:$B,G21,$D:$D) -> 82300
A22: 45678 | B22: August | C22: =IF(COUNTBLANK(#REF!)=0,#REF!,"Unknown") -> Food | D22: 6300 | E22: UPI
A23: 45679 | B23: September | C23: =IF(COUNTBLANK(#REF!)=0,#REF!,"Unknown") -> Rent | D23: 16000 | E23: Cash
A24: 45680 | B24: October | C24: =IF(COUNTBLANK(#REF!)=0,#REF!,"Unknown") -> Shopping | D24: 7600 | E24: Card
A25: 45681 | B25: November | C25: =IF(COUNTBLANK(#REF!)=0,#REF!,"Unknown") -> Investment | D25: 28000 | E25: NetBanking
A26: 45682 | B26: December | C26: =IF(COUNTBLANK(#REF!)=0,#REF!,"Unknown") -> Education | D26: 5300 | E26: UPI
A27: 45683 | B27: January | C27: =IF(COUNTBLANK(#REF!)=0,#REF!,"Unknown") -> Unknown | D27: 8600 | E27: Card
A28: 45733 | B28: February | C28: =IF(COUNTBLANK(#REF!)=0,#REF!,"Unknown") -> Travel | D28: 9400 | E28: UPI
A29: 45734 | B29: March | C29: =IF(COUNTBLANK(#REF!)=0,#REF!,"Unknown") -> Food | D29: 5200 | E29: Card
A30: 45735 | B30: April | C30: =IF(COUNTBLANK(#REF!)=0,#REF!,"Unknown") -> Investment | D30: 41000 | E30: Cheque
A31: 45736 | B31: May | C31: =IF(COUNTBLANK(#REF!)=0,#REF!,"Unknown") -> Utilities | D31: 6300 | E31: UPI
A32: 45737 | B32: June | C32: =IF(COUNTBLANK(#REF!)=0,#REF!,"Unknown") -> Transport | D32: 4800 | E32: Cash
A33: 45738 | B33: July | C33: =IF(COUNTBLANK(#REF!)=0,#REF!,"Unknown") -> Shopping | D33: 8100 | E33: Card
... A67: 45697 | B67: May | C67: =IF(COUNTBLANK(#REF!)=0,#REF!,"Unknown") -> Unknown | D67: 6100 | E67: Card
B68: June | C68: =IF(COUNTBLANK(#REF!)=0,#REF!,"Unknown") -> Rent | D68: 18000 | E68: UPI
A69: 45699 | B69: July | C69: =IF(COUNTBLANK(#REF!)=0,#REF!,"Unknown") -> Shopping | D69: 7900 | E69: UPI
A70: 45700 | B70: August | C70: =IF(COUNTBLANK(#REF!)=0,#REF!,"Unknown") -> Travel | D70: 10400 | E70: Card
A71: 45701 | B71: September | C71: =IF(COUNTBLANK(#REF!)=0,#REF!,"Unknown") -> Investment | D71: 36000 | E71: NetBanking
A72: 45702 | B72: October | C72: =IF(COUNTBLANK(#REF!)=0,#REF!,"Unknown") -> Utilities | D72: 5900 | E72: Cash
A73: 45703 | B73: November | C73: =IF(COUNTBLANK(#REF!)=0,#REF!,"Unknown") -> Healthcare | D73: 4100 | E73: UPI
...

Sheet Expense Pivot Table
A1: EXPENSE CATEGORY ANALYSIS
A3: Row Labels | B3: Sum of Expense Amount
A4: Education | B4: 19800
A5: Entertainment | B5: 22300
A6: Food | B6: 37400
A7: Groceries | B7: 38500
A8: Healthcare | B8: 42100
A9: Investment | B9: 183000
A10: Rent | B10: 291500
A11: Shopping | B11: 39000
A12: Transport | B12: 13900
A13: Travel | B13: 29900
A14: Unknown | B14: 35100
A15: Utilities | B15: 26500
A16: Grand Total | B16: 779000

Sheet Budget Sheet
A1: MONTHLY BUDGET ANALYSIS
A2: OUR BUDGET | D2: CALCULATION OF BUDGET
A3: Category | B3: Budget | D3: Category | E3: Monthly Budget | F3: Actual Expense | G3: Remaining Budget | H3: Status
A4: Rent | B4: 350000 | D4: Rent | E4: =VLOOKUP(D4,A4:B13,2,FALSE) -> 350000 | F4: =SUMIF('Expense Sheet'!$C:$C,D4,'Expense Sheet'!$D:$D) -> 327000 | G4: =(E4-F4) -> 23000 | H4: =IF(G4>=0,"Within Budget","Over Budget") -> Within Budget
A5: Groceries | B5: 30000 | D5: Groceries | E5: =VLOOKUP(D5,A5:B14,2,FALSE) -> 30000 | F5: =SUMIF('Expense Sheet'!$C:$C,D5,'Expense Sheet'!$D:$D) -> 38500 | G5: =(E5-F5) -> -8500 | H5: =IF(G5>=0,"Within Budget","Over Budget") -> Over Budget
A6: Food | B6: 45000 | D6: Food | E6: =VLOOKUP(D6,A6:B15,2,FALSE) -> 45000 | F6: =SUMIF('Expense Sheet'!$C:$C,D6,'Expense Sheet'!$D:$D) -> 41300 | G6: =(E6-F6) -> 3700 | H6: =IF(G6>=0,"Within Budget","Over Budget") -> Within Budget
A7: Utilities | B7: 30000 | D7: Utilities | E7: =VLOOKUP(D7,A7:B16,2,FALSE) -> 30000 | F7: =SUMIF('Expense Sheet'!$C:$C,D7,'Expense Sheet'!$D:$D) -> 44800 | G7: =(E7-F7) -> -14800 | H7: =IF(G7>=0,"Within Budget","Over Budget") -> Over Budget
A8: Entertainment | B8: 40000 | D8: Entertainment | E8: =VLOOKUP(D8,A8:B17,2,FALSE) -> 40000 | F8: =SUMIF('Expense Sheet'!$C:$C,D8,'Expense Sheet'!$D:$D) -> 34000 | G8: =(E8-F8) -> 6000 | H8: =IF(G8>=0,"Within Budget","Over Budget") -> Within Budget
A9: Healthcare | B9: 70000 | D9: Healthcare | E9: =VLOOKUP(D9,A9:B18,2,FALSE) -> 70000 | F9: =SUMIF('Expense Sheet'!$C:$C,D9,'Expense Sheet'!$D:$D) -> 56000 | G9: =(E9-F9) -> 14000 | H9: =IF(G9>=0,"Within Budget","Over Budget") -> Within Budget
A10: Education | B10: 30000 | D10: Education | E10: =VLOOKUP(D10,A10:B19,2,FALSE) -> 30000 | F10: =SUMIF('Expense Sheet'!$C:$C,D10,'Expense Sheet'!$D:$D) -> 23700 | G10: =(E10-F10) -> 6300 | H10: =IF(G10>=0,"Within Budget","Over Budget") -> Within Budget
A11: Transport | B11: 30000 | D11: Transport | E11: =VLOOKUP(D11,A11:B20,2,FALSE) -> 30000 | F11: =SUMIF('Expense Sheet'!$C:$C,D11,'Expense Sheet'!$D:$D) -> 23100 | G11: =(E11-F11) -> 6900 | H11: =IF(G11>=0,"Within Budget","Over Budget") -> Within Budget
A12: Shopping | B12: 90000 | D12: Shopping | E12: =VLOOKUP(D12,A12:B21,2,FALSE) -> 90000 | F12: =SUMIF('Expense Sheet'!$C:$C,D12,'Expense Sheet'!$D:$D) -> 78900 | G12: =(E12-F12) -> 11100 | H12: =IF(G12>=0,"Within Budget","Over Budget") -> Within Budget
A13: Investment | B13: 350000 | D13: Investment | E13: =VLOOKUP(D13,A13:B22,2,FALSE) -> 350000 | F13: =SUMIF('Expense Sheet'!$C:$C,D13,'Expense Sheet'!$D:$D) -> 344000 | G13: =(E13-F13) -> 6000 | H13: =IF(G13>=0,"Within Budget","Over Budget") -> Within Budget

Sheet Budget Pivot Table
A1: BUDGET VS ACTUAL ANALYSIS
A3: Row Labels | B3: Sum of Monthly Budget | C3: Sum of Actual Expense
A4: Education | B4: 30000 | C4: 23700
A5: Entertainment | B5: 40000 | C5: 34000
A6: Food | B6: 45000 | C6: 41300
A7: Groceries | B7: 30000 | C7: 38500
A8: Healthcare | B8: 70000 | C8: 56000
A9: Investment | B9: 350000 | C9: 344000
A10: Rent | B10: 350000 | C10: 327000
A11: Shopping | B11: 90000 | C11: 78900
A12: Transport | B12: 30000 | C12: 23100
A13: Utilities | B13: 30000 | C13: 44800
A14: Grand Total | B14: 1065000 | C14: 1011300

Sheet Dashboard
A1: PERSONAL FINANCE & BUDGET PLANNER | Q1: Data Period: Jan 2025-Dec 2025
A2: FINAL ANALYSIS DASHBOARD
A3: 💰 Total Income | E3: 💸 Total Expense | I3: 🏦 Total Savings | M3: 📊 Remaining Budget | Q3: 💳 Avg Credit Score
A4: ₹78,71,000 | E4: ₹7,79,000 | I4: ₹10,11,300 | M4: ₹2,69,300 | Q4: 742
A6: Total yearly income | E6: Total expenses recorded | I6: Total savings accumulated | M6: Budget left after expenses | Q6: Average financial score
A7: 📈 Monthly Income Trend | K7: 💸 Expense Category Analysis
F24: 📊 Budget vs Actual Analysis

Sheet Pivot Tables
A1: PIVOT ANALYSIS TABLES
A2: MONTHLY INCOME SUMMARY | D2: EXPENSE CATEGORY SUMMARY | G2: BUDGET VS ACTUAL SUMMARY
A3: Row Labels | B3: Sum of Monthly Income | D3: Row Labels | E3: Sum of Expense Amount | G3: Row Labels | H3: Sum of Monthly Budget | I3: Sum of Actual Expense
A4: January | B4: 605000 | D4: Education | E4: 19800 | G4: Education | H4: 30000 | I4: 23700
A5: February | B5: 681000 | D5: Entertainment | E5: 22300 | G5: Entertainment | H5: 40000 | I5: 34000
A6: March | B6: 570000 | D6: Food | E6: 37400 | G6: Food | H6: 45000 | I6: 41300
A7: April | B7: 817000 | D7: Groceries | E7: 38500 | G7: Groceries | H7: 30000 | I7: 38500
A8: May | B8: 552000 | D8: Healthcare | E8: 42100 | G8: Healthcare | H8: 70000 | I8: 56000
A9: June | B9: 639000 | D9: Investment | E9: 183000 | G9: Investment | H9: 350000 | I9: 344000
A10: July | B10: 731000 | D10: Rent | E10: 291500 | G10: Rent | H10: 350000 | I10: 327000
A11: August | B11: 630000 | D11: Shopping | E11: 39000 | G11: Shopping | H11: 90000 | I11: 78900
A12: September | B12: 661000 | D12: Transport | E12: 13900 | G12: Transport | H12: 30000 | I12: 23100
A13: October | B13: 465000 | D13: Travel | E13: 29900 | G13: Utilities | H13: 30000 | I13: 44800
A14: November | B14: 825000 | D14: Unknown | E14: 35100 | G14: Grand Total | H14: 1065000 | I14: 1011300
A15: December | B15: 695000 | D15: Utilities | E15: 26500
A16: Grand Total | B16: 7871000 | D16: Grand Total | E16: 779000
